export class AppError extends Error {
  constructor(message, statusCode) {
    super(message);
    this.statusCode = statusCode;
    this.isOperational = true;
    Error.captureStackTrace(this, this.constructor);
  }
}

export class ValidationError extends AppError {
  constructor(message) {
    super(message, 400);
  }
}

export class AuthenticationError extends AppError {
  constructor(message = 'Authentication failed') {
    super(message, 401);
  }
}

export class AuthorizationError extends AppError {
  constructor(message = 'Access denied') {
    super(message, 403);
  }
}

export class NotFoundError extends AppError {
  constructor(message = 'Resource not found') {
    super(message, 404);
  }
}

export class ConflictError extends AppError {
  constructor(message = 'Resource already exists') {
    super(message, 409);
  }
}

export const errorHandler = (err, req, res, next) => {
  let { statusCode = 500, message } = err;

  if (!err.isOperational) {
    statusCode = 500;
    message = 'Internal server error';
    console.error('Unexpected error:', err);
  }

  res.status(statusCode).json({
    status: 'error',
    statusCode,
    message,
    ...(process.env.NODE_ENV === 'development' && { stack: err.stack }),
  });
};

export const asyncHandler = (fn) => {
  return (req, res, next) => {
    Promise.resolve(fn(req, res, next)).catch(next);
  };
};
